Workbook

Sheet Home
A1: invoice_id | B1: Index | C1: product | D1: q | E1: unit_cost | F1: total | G1: unit_price | H1: q_sold | I1: total_sold | J1: total_cost_sold | K1: net | L1: q_stil | M1: cost_stil | N1: net_per_one
A2: 2127 | B2: 143 | C2: صنادل فرو أطفال شكل فواكة | D2: 4 | E2: 900 | F2: =D2*E2 -> 3600 | G2: 1000 | H2: 4 | I2: =G2*H2 -> 4000 | J2: =H2*E2 -> 3600 | K2: =I2-J2 -> 400 | L2: =D2-H2 -> 0 | M2: =L2*E2 -> 0 | N2: =Table3[[#This Row],[unit_price]]-Table3[[#This Row],[unit_cost]] -> 100
A3: 2127 | B3: 142 | C3: صنادل فرو أطفال اشكال | D3: 2 | E3: 700 | F3: =D3*E3 -> 1400 | G3: 900 | H3: 0 | I3: =G3*H3 -> 0 | J3: =H3*E3 -> 0 | K3: =I3-J3 -> 0 | L3: =D3-H3 -> 2 | M3: =L3*E3 -> 1400 | N3: =Table3[[#This Row],[unit_price]]-Table3[[#This Row],[unit_cost]] -> 200
A4: 2127 | B4: 141 | C4: قفاز مع الضوء 3823 | D4: 1 | E4: 650 | F4: =D4*E4 -> 650 | G4: 900 | H4: 1 | I4: =G4*H4 -> 900 | J4: =H4*E4 -> 650 | K4: =I4-J4 -> 250 | L4: =D4-H4 -> 0 | M4: =L4*E4 -> 0 | N4: =Table3[[#This Row],[unit_price]]-Table3[[#This Row],[unit_cost]] -> 250
A5: 2127 | B5: 140 | C5: كوب استيل جديد مع مصاصة | D5: 1 | E5: 2800 | F5: =D5*E5 -> 2800 | G5: 3200 | H5: 1 | I5: =G5*H5 -> 3200 | J5: =H5*E5 -> 2800 | K5: =I5-J5 -> 400 | L5: =D5-H5 -> 0 | M5: =L5*E5 -> 0 | N5: =Table3[[#This Row],[unit_price]]-Table3[[#This Row],[unit_cost]] -> 400
A6: 2127 | B6: 139 | C6: قطاعة يدوي سحاب خيط سحاب | D6: 1 | E6: 1200 | F6: =D6*E6 -> 1200 | G6: 1500 | H6: 1 | I6: =G6*H6 -> 1500 | J6: =H6*E6 -> 1200 | K6: =I6-J6 -> 300 | L6: =D6-H6 -> 0 | M6: =L6*E6 -> 0 | N6: =Table3[[#This Row],[unit_price]]-Table3[[#This Row],[unit_cost]] -> 300
A7: 2123 | B7: 139 | C7: رشاش اربيجي كهربائي | D7: 3 | E7: 4250 | F7: =D7*E7 -> 12750 | G7: 4700 | H7: 3 | I7: =G7*H7 -> 14100 | J7: =H7*E7 -> 12750 | K7: =I7-J7 -> 1350 | L7: =D7-H7 -> 0 | M7: =L7*E7 -> 0 | N7: =Table3[[#This Row],[unit_price]]-Table3[[#This Row],[unit_cost]] -> 450
A8: 2122 | B8: 138 | C8: منشفه مضغوطه للاستخدام مره واحده ١*٢٠ حبه - | D8: 10 | E8: 400 | F8: 4000 | G8: 500 | H8: 4 | I8: =G8*H8 -> 2000 | J8: =H8*E8 -> 1600 | K8: =I8-J8 -> 400 | L8: =D8-H8 -> 6 | M8: =L8*E8 -> 2400 | N8: =Table3[[#This Row],[unit_price]]-Table3[[#This Row],[unit_cost]] -> 100
A9: 2083 | B9: 138 | C9: منشفه مضغوطه للاستخدام مره واحده ١*٢٠ حبه - | D9: 20 | E9: 450 | F9: 9000 | G9: 500 | H9: 23 | I9: =G9*H9 -> 11500 | J9: =H9*E9 -> 10350 | K9: =I9-J9 -> 1150 | L9: =D9-H9 -> -3 | M9: =L9*E9 -> -1350 | N9: =Table3[[#This Row],[unit_price]]-Table3[[#This Row],[unit_cost]] -> 50
A10: 2122 | B10: 137 | C10: مناديل مبلله للوجه منوع روائح ماركه HP 25قطعه | D10: 12 | E10: 250 | F10: 3000 | G10: 270 | H10: 0 | I10: =G10*H10 -> 0 | J10: =H10*E10 -> 0 | K10: =I10-J10 -> 0 | L10: =D10-H10 -> 12 | M10: =L10*E10 -> 3000 | N10: =Table3[[#This Row],[unit_price]]-Table3[[#This Row],[unit_cost]] -> 20
A11: 2083 | B11: 137 | C11: مناديل مبلله للوجه منوع روائح ماركه HP 25قطعه | D11: 24 | E11: 250 | F11: 6000 | G11: 280 | H11: 21 | I11: =G11*H11 -> 5880 | J11: =H11*E11 -> 5250 | K11: =I11-J11 -> 630 | L11: =D11-H11 -> 3 | M11: =L11*E11 -> 750 | N11: =Table3[[#This Row],[unit_price]]-Table3[[#This Row],[unit_cost]] -> 30
A12: 2122 | B12: 136 | C12: مناديل مبلل سيتستيف ٩٠ منديل | D12: 12 | E12: 400 | F12: 4800 | G12: 420 | H12: 10 | I12: =G12*H12 -> 4200 | J12: =H12*E12 -> 4000 | K12: =I12-J12 -> 200 | L12: =D12-H12 -> 2 | M12: =L12*E12 -> 800 | N12: =Table3[[#This Row],[unit_price]]-Table3[[#This Row],[unit_cost]] -> 20
A13: 2083 | B13: 136 | C13: مناديل مبلل سيتستيف ٩٠ منديل | D13: 24 | E13: 400 | F13: 9600 | G13: 420 | H13: 24 | I13: =G13*H13 -> 10080 | J13: =H13*E13 -> 9600 | K13: =I13-J13 -> 480 | L13: =D13-H13 -> 0 | M13: =L13*E13 -> 0 | N13: =Table3[[#This Row],[unit_price]]-Table3[[#This Row],[unit_cost]] -> 20
A14: 2122 | B14: 135 | C14: ملخاخ اسنان ابو ٣ طقم طرد ٤٠٣٩ | D14: 24 | E14: 120 | F14: 2880 | G14: 135 | H14: 14 | I14: =G14*H14 -> 1890 | J14: =H14*E14 -> 1680 | K14: =I14-J14 -> 210 | L14: =D14-H14 -> 10 | M14: =L14*E14 -> 1200 | N14: =Table3[[#This Row],[unit_price]]-Table3[[#This Row],[unit_cost]] -> 15
A15: 2083 | B15: 135 | C15: ملخاخ اسنان ابو ٣ طقم طرد ٤٠٣٩ | D15: 48 | E15: 120 | F15: 5760 | G15: 135 | H15: 48 | I15: =G15*H15 -> 6480 | J15: =H15*E15 -> 5760 | K15: =I15-J15 -> 720 | L15: =D15-H15 -> 0 | M15: =L15*E15 -> 0 | N15: =Table3[[#This Row],[unit_price]]-Table3[[#This Row],[unit_cost]] -> 15
A16: 2083 | B16: 134 | C16: مج استيل AKD-51916 | D16: 3 | E16: 1200 | F16: 3600 | G16: 1400 | H16: 2 | I16: =G16*H16 -> 2800 | J16: =H16*E16 -> 2400 | K16: =I16-J16 -> 400 | L16: =D16-H16 -> 1 | M16: =L16*E16 -> 1200 | N16: =Table3[[#This Row],[unit_price]]-Table3[[#This Row],[unit_cost]] -> 200
A17: 2122 | B17: 133 | C17: لوح العاب مغناطيس CT8001 30*1 رقم ٢٤٨ | D17: 3 | E17: 650 | F17: 1950 | G17: 1000 | H17: 1 | I17: =G17*H17 -> 1000 | J17: =H17*E17 -> 650 | K17: =I17-J17 -> 350 | L17: =D17-H17 -> 2 | M17: =L17*E17 -> 1300 | N17: =Table3[[#This Row],[unit_price]]-Table3[[#This Row],[unit_cost]] -> 350
A18: 2083 | B18: 133 | C18: لوح العاب مغناطيس CT8001 30*1 رقم ٢٤٨ | D18: 6 | E18: 700 | F18: 4200 | G18: 1000 | H18: 6 | I18: =G18*H18 -> 6000 | J18: =H18*E18 -> 4200 | K18: =I18-J18 -> 1800 | L18: =D18-H18 -> 0 | M18: =L18*E18 -> 0 | N18: =Table3[[#This Row],[unit_price]]-Table3[[#This Row],[unit_cost]] -> 300
A19: 2083 | B19: 132 | C19: لعبه يورو بحر ٤٠٠ | D19: 36 | E19: 250 | F19: 9000 | G19: 300 | H19: 36 | I19: =G19*H19 -> 10800 | J19: =H19*E19 -> 9000 | K19: =I19-J19 -> 1800 | L19: =D19-H19 -> 0 | M19: =L19*E19 -> 0 | N19: =Table3[[#This Row],[unit_price]]-Table3[[#This Row],[unit_cost]] -> 50
... A27: 2083 | B27: 125 | C27: كوب زجاج كبير عطاء كشبي MR-215 | D27: 6 | E27: 900 | F27: 5400 | G27: 900 | H27: 4 | I27: =G27*H27 -> 3600 | J27: =H27*E27 -> 3600 | K27: =I27-J27 -> 0 | L27: =D27-H27 -> 2 | M27: =L27*E27 -> 1800 | N27: =Table3[[#This Row],[unit_price]]-Table3[[#This Row],[unit_cost]] -> 0
A28: 2123 | B28: 124 | C28: كوب خلاط كايتشينو ٣٢١٥ | D28: 2 | E28: 750 | F28: =D28*E28 -> 1500 | G28: 950 | H28: 0 | I28: =G28*H28 -> 0 | J28: =H28*E28 -> 0 | K28: =I28-J28 -> 0 | L28: =D28-H28 -> 2 | M28: =L28*E28 -> 1500 | N28: =Table3[[#This Row],[unit_price]]-Table3[[#This Row],[unit_cost]] -> 200
A29: 2122 | B29: 124 | C29: كوب خلاط كايتشينو ٣٢١٥ | D29: 4 | E29: 750 | F29: 3000 | G29: 950 | H29: 0 | I29: =G29*H29 -> 0 | J29: =H29*E29 -> 0 | K29: =I29-J29 -> 0 | L29: =D29-H29 -> 4 | M29: =L29*E29 -> 3000 | N29: =Table3[[#This Row],[unit_price]]-Table3[[#This Row],[unit_cost]] -> 200
A30: 2083 | B30: 124 | C30: كوب خلاط كايتشينو ٣٢١٥ | D30: 6 | E30: 850 | F30: 5100 | G30: 950 | H30: 3 | I30: =G30*H30 -> 2850 | J30: =H30*E30 -> 2550 | K30: =I30-J30 -> 300 | L30: =D30-H30 -> 3 | M30: =L30*E30 -> 2550 | N30: =Table3[[#This Row],[unit_price]]-Table3[[#This Row],[unit_cost]] -> 100
A31: 2083 | B31: 123 | C31: قلام رسم تحديد - ٣٧٦ | D31: 60 | E31: 60 | F31: 3600 | G31: 65 | H31: 60 | I31: =G31*H31 -> 3900 | J31: =H31*E31 -> 3600 | K31: =I31-J31 -> 300 | L31: =D31-H31 -> 0 | M31: =L31*E31 -> 0 | N31: =Table3[[#This Row],[unit_price]]-Table3[[#This Row],[unit_cost]] -> 5
A32: 2083 | B32: 122 | C32: قطاعه موز شرائح ٦ ملقات - MR-266 +١٢١ | D32: 1 | E32: 600 | F32: 600 | G32: 600 | H32: 1 | I32: =G32*H32 -> 600 | J32: =H32*E32 -> 600 | K32: =I32-J32 -> 0 | L32: =D32-H32 -> 0 | M32: =L32*E32 -> 0 | N32: =Table3[[#This Row],[unit_price]]-Table3[[#This Row],[unit_cost]] -> 0
A33: 2083 | B33: 121 | C33: عبة سيارات سباق مرتفع MR-96 | D33: 8 | E33: 500 | F33: 4000 | G33: 470 | H33: 8 | I33: =G33*H33 -> 3760 | J33: =H33*E33 -> 4000 | K33: =I33-J33 -> -240 | L33: =D33-H33 -> 0 | M33: =L33*E33 -> 0 | N33: =Table3[[#This Row],[unit_price]]-Table3[[#This Row],[unit_cost]] -> -30
A34: 2083 | B34: 120 | C34: ضافر صناعي اطقال YM-T002 414 | D34: 24 | E34: 250 | F34: 6000 | G34: 260 | H34: 0 | I34: =G34*H34 -> 0 | J34: =H34*E34 -> 0 | K34: =I34-J34 -> 0 | L34: =D34-H34 -> 24 | M34: =L34*E34 -> 6000 | N34: =Table3[[#This Row],[unit_price]]-Table3[[#This Row],[unit_cost]] -> 10
A35: 2123 | B35: 119 | C35: صنادل منزليه نسائي فرو ازرق +لبني | D35: 6 | E35: 750 | F35: =D35*E35 -> 4500 | G35: 900 | H35: 5 | I35: =G35*H35 -> 4500 | J35: =H35*E35 -> 3750 | K35: =I35-J35 -> 750 | L35: =D35-H35 -> 1 | M35: =L35*E35 -> 750 | N35: =Table3[[#This Row],[unit_price]]-Table3[[#This Row],[unit_cost]] -> 150
A36: 2122 | B36: 119 | C36: صنادل منزليه نسائي فرو ازرق +لبني | D36: 12 | E36: 750 | F36: 9000 | G36: 900 | H36: 12 | I36: =G36*H36 -> 10800 | J36: =H36*E36 -> 9000 | K36: =I36-J36 -> 1800 | L36: =D36-H36 -> 0 | M36: =L36*E36 -> 0 | N36: =Table3[[#This Row],[unit_price]]-Table3[[#This Row],[unit_cost]] -> 150
A37: 2083 | B37: 119 | C37: صنادل منزليه نسائي فرو ازرق +لبني | D37: 6 | E37: 750 | F37: 4500 | G37: 900 | H37: 6 | I37: =G37*H37 -> 5400 | J37: =H37*E37 -> 4500 | K37: =I37-J37 -> 900 | L37: =D37-H37 -> 0 | M37: =L37*E37 -> 0 | N37: =Table3[[#This Row],[unit_price]]-Table3[[#This Row],[unit_cost]] -> 150
A38: 2122 | B38: 118 | C38: صنادل منزليه MR-131 | D38: 12 | E38: 600 | F38: 7200 | G38: 750 | H38: 8 | I38: =G38*H38 -> 6000 | J38: =H38*E38 -> 4800 | K38: =I38-J38 -> 1200 | L38: =D38-H38 -> 4 | M38: =L38*E38 -> 2400 | N38: =Table3[[#This Row],[unit_price]]-Table3[[#This Row],[unit_cost]] -> 150
A39: 2083 | B39: 118 | C39: صنادل منزليه MR-131 | D39: 12 | E39: 600 | F39: 7200 | G39: 750 | H39: 12 | I39: =G39*H39 -> 9000 | J39: =H39*E39 -> 7200 | K39: =I39-J39 -> 1800 | L39: =D39-H39 -> 0 | M39: =L39*E39 -> 0 | N39: =Table3[[#This Row],[unit_price]]-Table3[[#This Row],[unit_cost]] -> 150
A40: 2083 | B40: 117 | C40: شموع ضوئيه بلاستيكيه صغيره MR-A20 | D40: 24 | E40: 150 | F40: 3600 | G40: 175 | H40: 24 | I40: =G40*H40 -> 4200 | J40: =H40*E40 -> 3600 | K40: =I40-J40 -> 600 | L40: =D40-H40 -> 0 | M40: =L40*E40 -> 0 | N40: =Table3[[#This Row],[unit_price]]-Table3[[#This Row],[unit_cost]] -> 25
A41: 2083 | B41: 116 | C41: شموع ضونيه بلاستيكيه MR-A22 | D41: 12 | E41: 650 | F41: 7800 | G41: 670 | H41: 12 | I41: =G41*H41 -> 8040 | J41: =H41*E41 -> 7800 | K41: =I41-J41 -> 240 | L41: =D41-H41 -> 0 | M41: =L41*E41 -> 0 | N41: =Table3[[#This Row],[unit_price]]-Table3[[#This Row],[unit_cost]] -> 20
A42: 2122 | B42: 115 | C42: شرابات صحية قطن طبيعي لمرضى السكر - ٩٢٤ | D42: 12 | E42: 650 | F42: 7800 | G42: 900 | H42: 12 | I42: =G42*H42 -> 10800 | J42: =H42*E42 -> 7800 | K42: =I42-J42 -> 3000 | L42: =D42-H42 -> 0 | M42: =L42*E42 -> 0 | N42: =Table3[[#This Row],[unit_price]]-Table3[[#This Row],[unit_cost]] -> 250
A43: 2083 | B43: 115 | C43: شرابات صحية قطن طبيعي لمرضى السكر - ٩٢٤ | D43: 12 | E43: 800 | F43: 9600 | G43: 825 | H43: 12 | I43: =G43*H43 -> 9900 | J43: =H43*E43 -> 9600 | K43: =I43-J43 -> 300 | L43: =D43-H43 -> 0 | M43: =L43*E43 -> 0 | N43: =Table3[[#This Row],[unit_price]]-Table3[[#This Row],[unit_cost]] -> 25
A44: 2083 | B44: 114 | C44: سفره طاوله ١٥٢*١٣٧ - طرد ٣١١٢ | D44: 12 | E44: 400 | F44: 4800 | G44: 400 | H44: 5 | I44: =G44*H44 -> 2000 | J44: =H44*E44 -> 2000 | K44: =I44-J44 -> 0 | L44: =D44-H44 -> 7 | M44: =L44*E44 -> 2800 | N44: =Table3[[#This Row],[unit_price]]-Table3[[#This Row],[unit_cost]] -> 0
A45: 2083 | B45: 113 | C45: سفره طاوله ١٣٧٠٩٠ | D45: 12 | E45: 250 | F45: 3000 | G45: 333 | H45: 5 | I45: =G45*H45 -> 1665 | J45: =H45*E45 -> 1250 | K45: =I45-J45 -> 415 | L45: =D45-H45 -> 7 | M45: =L45*E45 -> 1750 | N45: =Table3[[#This Row],[unit_price]]-Table3[[#This Row],[unit_cost]] -> 83
A46: 2083 | B46: 112 | C46: سفره طاولة 137*137 | D46: 12 | E46: 350 | F46: 4200 | G46: 400 | H46: 4 | I46: =G46*H46 -> 1600 | J46: =H46*E46 -> 1400 | K46: =I46-J46 -> 200 | L46: =D46-H46 -> 8 | M46: =L46*E46 -> 2800 | N46: =Table3[[#This Row],[unit_price]]-Table3[[#This Row],[unit_cost]] -> 50
A47: 2083 | B47: 111 | C47: ساعات يد اطفال لمس منوع طرد MR-380 | D47: 24 | E47: 400 | F47: 9600 | G47: 500 | H47: 7 | I47: =G47*H47 -> 3500 | J47: =H47*E47 -> 2800 | K47: =I47-J47 -> 700 | L47: =D47-H47 -> 17 | M47: =L47*E47 -> 6800 | N47: =Table3[[#This Row],[unit_price]]-Table3[[#This Row],[unit_cost]] -> 100
...

Sheet invoice
A1: invoce_id | B1: id | C1: customer | D1: product_id | E1: product | F1: q | G1: unit_price | H1: total
A2: 1 | B2: 1001 | C2: الصعيدي | D2: 127 | E2: =VLOOKUP(D2, Home!$B$2:$C$100, 2, FALSE) -> لعاب صابون فقاعات حروف انجليزيه MR-A93 | F2: 48 | G2: =VLOOKUP(D2, Home!$B$2:$G$1002, 6, FALSE) -> 45 | H2: =F2*G2 -> 2160
A3: 1 | B3: 1001 | C3: الصعيدي | D3: 117 | E3: =VLOOKUP(D3, Home!$B$2:$C$100, 2, FALSE) -> شموع ضوئيه بلاستيكيه صغيره MR-A20 | F3: 24 | G3: =VLOOKUP(D3, Home!$B$2:$G$1002, 6, FALSE) -> 175 | H3: =F3*G3 -> 4200
A4: 1 | B4: 1001 | C4: الصعيدي | D4: 115 | E4: =VLOOKUP(D4, Home!$B$2:$C$100, 2, FALSE) -> شرابات صحية قطن طبيعي لمرضى السكر - ٩٢٤ | F4: 6 | G4: =VLOOKUP(D4, Home!$B$2:$G$1002, 6, FALSE) -> 900 | H4: =F4*G4 -> 5400
A5: 1 | B5: 1001 | C5: الصعيدي | D5: 138 | E5: =VLOOKUP(D5, Home!$B$2:$C$100, 2, FALSE) -> منشفه مضغوطه للاستخدام مره واحده ١*٢٠ حبه - | F5: 1 | G5: =VLOOKUP(D5, Home!$B$2:$G$1002, 6, FALSE) -> 500 | H5: =F5*G5 -> 500
A6: 1 | B6: 1001 | C6: الصعيدي | D6: 126 | E6: =VLOOKUP(D6, Home!$B$2:$C$100, 2, FALSE) -> كوب زجاج كبير غطاء خشبي MR-214 | F6: 1 | G6: =VLOOKUP(D6, Home!$B$2:$G$1002, 6, FALSE) -> 900 | H6: =F6*G6 -> 900
A7: 1 | B7: 1001 | C7: الصعيدي | D7: 125 | E7: =VLOOKUP(D7, Home!$B$2:$C$100, 2, FALSE) -> كوب زجاج كبير عطاء كشبي MR-215 | F7: 1 | G7: =VLOOKUP(D7, Home!$B$2:$G$1002, 6, FALSE) -> 900 | H7: =F7*G7 -> 900
A8: 1 | B8: 1001 | C8: الصعيدي | D8: 124 | E8: =VLOOKUP(D8, Home!$B$2:$C$100, 2, FALSE) -> كوب خلاط كايتشينو ٣٢١٥ | F8: 1 | G8: =VLOOKUP(D8, Home!$B$2:$G$1002, 6, FALSE) -> 950 | H8: =F8*G8 -> 950
A9: 1 | B9: 1001 | C9: الصعيدي | D9: 110 | E9: =VLOOKUP(D9, Home!$B$2:$C$100, 2, FALSE) -> حافظه استيل حساس رقمي ٥٠٠ مل MR- | F9: 6 | G9: =VLOOKUP(D9, Home!$B$2:$G$1002, 6, FALSE) -> 900 | H9: =F9*G9 -> 5400
A10: 1 | B10: 1001 | C10: الصعيدي | D10: 118 | E10: =VLOOKUP(D10, Home!$B$2:$C$100, 2, FALSE) -> صنادل منزليه MR-131 | F10: 2 | G10: =VLOOKUP(D10, Home!$B$2:$G$1002, 6, FALSE) -> 750 | H10: =F10*G10 -> 1500
A11: 1 | B11: 1001 | C11: الصعيدي | D11: 119 | E11: =VLOOKUP(D11, Home!$B$2:$C$100, 2, FALSE) -> صنادل منزليه نسائي فرو ازرق +لبني | F11: 1 | G11: =VLOOKUP(D11, Home!$B$2:$G$1002, 6, FALSE) -> 900 | H11: =F11*G11 -> 900
A12: 1 | B12: 1001 | C12: الصعيدي | D12: 132 | E12: =VLOOKUP(D12, Home!$B$2:$C$100, 2, FALSE) -> لعبه يورو بحر ٤٠٠ | F12: 12 | G12: =VLOOKUP(D12, Home!$B$2:$G$1002, 6, FALSE) -> 300 | H12: =F12*G12 -> 3600
A13: 1 | B13: 1001 | C13: الصعيدي | D13: 121 | E13: =VLOOKUP(D13, Home!$B$2:$C$100, 2, FALSE) -> عبة سيارات سباق مرتفع MR-96 | F13: 5 | G13: =VLOOKUP(D13, Home!$B$2:$G$1002, 6, FALSE) -> 470 | H13: =F13*G13 -> 2350
A14: 1 | B14: 1001 | C14: الصعيدي | D14: 128 | E14: =VLOOKUP(D14, Home!$B$2:$C$100, 2, FALSE) -> لعبة الغاز OMG طرد ٢٥٠ | F14: 4 | G14: =VLOOKUP(D14, Home!$B$2:$G$1002, 6, FALSE) -> 470 | H14: =F14*G14 -> 1880 | I14: =SUM(H2:H14) -> 30640
A15: 2 | B15: 1010 | C15: سوبر فتحة قبل الكريمي | D15: 127 | E15: =VLOOKUP(D15, Home!$B$2:$C$100, 2, FALSE) -> لعاب صابون فقاعات حروف انجليزيه MR-A93 | F15: 48 | G15: =VLOOKUP(D15, Home!$B$2:$G$1002, 6, FALSE) -> 45 | H15: =F15*G15 -> 2160
A16: 2 | B16: 1010 | C16: سوبر فتحة قبل الكريمي | D16: 138 | E16: =VLOOKUP(D16, Home!$B$2:$C$100, 2, FALSE) -> منشفه مضغوطه للاستخدام مره واحده ١*٢٠ حبه - | F16: 1 | G16: =VLOOKUP(D16, Home!$B$2:$G$1002, 6, FALSE) -> 500 | H16: =F16*G16 -> 500 | I16: 2900
A17: 3 | B17: 1002 | C17: عزام الشميري | D17: 127 | E17: =VLOOKUP(D17, Home!$B$2:$C$100, 2, FALSE) -> لعاب صابون فقاعات حروف انجليزيه MR-A93 | F17: 48 | G17: =VLOOKUP(D17, Home!$B$2:$G$1002, 6, FALSE) -> 45 | H17: =F17*G17 -> 2160
A18: 3 | B18: 1002 | C18: عزام الشميري | D18: 133 | E18: =VLOOKUP(D18, Home!$B$2:$C$100, 2, FALSE) -> لوح العاب مغناطيس CT8001 30*1 رقم ٢٤٨ | F18: 1 | G18: =VLOOKUP(D18, Home!$B$2:$G$1002, 6, FALSE) -> 1000 | H18: =F18*G18 -> 1000
A19: 3 | B19: 1002 | C19: عزام الشميري | D19: 138 | E19: =VLOOKUP(D19, Home!$B$2:$C$100, 2, FALSE) -> منشفه مضغوطه للاستخدام مره واحده ١*٢٠ حبه - | F19: 1 | G19: =VLOOKUP(D19, Home!$B$2:$G$1002, 6, FALSE) -> 500 | H19: =F19*G19 -> 500 | I19: =SUM(H17:H19) -> 3660
A20: 4 | B20: 1002 | C20: عزام الشميري | D20: 133 | E20: =VLOOKUP(D20, Home!$B$2:$C$100, 2, FALSE) -> لوح العاب مغناطيس CT8001 30*1 رقم ٢٤٨ | F20: 1 | G20: =VLOOKUP(D20, Home!$B$2:$G$1002, 6, FALSE) -> 1000 | H20: =F20*G20 -> 1000 | I20: 1000
A21: 5 | B21: 1002 | C21: عزام الشميري | D21: 133 | E21: =VLOOKUP(D21, Home!$B$2:$C$100, 2, FALSE) -> لوح العاب مغناطيس CT8001 30*1 رقم ٢٤٨ | F21: 1 | G21: =VLOOKUP(D21, Home!$B$2:$G$1002, 6, FALSE) -> 1000 | H21: =F21*G21 -> 1000 | I21: 1000
A22: 6 | B22: 1011 | C22: اكسسوارات الدايري | D22: 109 | E22: =VLOOKUP(D22, Home!$B$2:$C$100, 2, FALSE) -> جلاس تلفونات جداري ١١٢ | F22: 1 | G22: =VLOOKUP(D22, Home!$B$2:$G$1002, 6, FALSE) -> 400 | H22: =F22*G22 -> 400 | I22: 400
A23: 7 | B23: 1000 | C23: حسن الدرة | D23: 115 | E23: =VLOOKUP(D23, Home!$B$2:$C$100, 2, FALSE) -> شرابات صحية قطن طبيعي لمرضى السكر - ٩٢٤ | F23: 1 | G23: =VLOOKUP(D23, Home!$B$2:$G$1002, 6, FALSE) -> 900 | H23: =F23*G23 -> 900
A24: 7 | B24: 1000 | C24: حسن الدرة | D24: 137 | E24: =VLOOKUP(D24, Home!$B$2:$C$100, 2, FALSE) -> مناديل مبلله للوجه منوع روائح ماركه HP 25قطعه | F24: 2 | G24: =VLOOKUP(D24, Home!$B$2:$G$1002, 6, FALSE) -> 270 | H24: =F24*G24 -> 540
A25: 7 | B25: 1000 | C25: حسن الدرة | D25: 136 | E25: =VLOOKUP(D25, Home!$B$2:$C$100, 2, FALSE) -> مناديل مبلل سيتستيف ٩٠ منديل | F25: 1 | G25: =VLOOKUP(D25, Home!$B$2:$G$1002, 6, FALSE) -> 420 | H25: =F25*G25 -> 420
A26: 7 | B26: 1000 | C26: حسن الدرة | D26: 118 | E26: =VLOOKUP(D26, Home!$B$2:$C$100, 2, FALSE) -> صنادل منزليه MR-131 | F26: 1 | G26: =VLOOKUP(D26, Home!$B$2:$G$1002, 6, FALSE) -> 750 | H26: =F26*G26 -> 750
A27: 7 | B27: 1000 | C27: حسن الدرة | D27: 119 | E27: =VLOOKUP(D27, Home!$B$2:$C$100, 2, FALSE) -> صنادل منزليه نسائي فرو ازرق +لبني | F27: 1 | G27: =VLOOKUP(D27, Home!$B$2:$G$1002, 6, FALSE) -> 900 | H27: =F27*G27 -> 900
A28: 7 | B28: 1000 | C28: حسن الدرة | D28: 135 | E28: =VLOOKUP(D28, Home!$B$2:$C$100, 2, FALSE) -> ملخاخ اسنان ابو ٣ طقم طرد ٤٠٣٩ | F28: 6 | G28: =VLOOKUP(D28, Home!$B$2:$G$1002, 6, FALSE) -> 135 | H28: =F28*G28 -> 810
A29: 7 | B29: 1000 | C29: حسن الدرة | D29: 138 | E29: =VLOOKUP(D29, Home!$B$2:$C$100, 2, FALSE) -> منشفه مضغوطه للاستخدام مره واحده ١*٢٠ حبه - | F29: 1 | G29: =VLOOKUP(D29, Home!$B$2:$G$1002, 6, FALSE) -> 500 | H29: =F29*G29 -> 500
A30: 7 | B30: 1000 | C30: حسن الدرة | D30: 112 | E30: =VLOOKUP(D30, Home!$B$2:$C$100, 2, FALSE) -> سفره طاولة 137*137 | F30: 1 | G30: =VLOOKUP(D30, Home!$B$2:$G$1002, 6, FALSE) -> 400 | H30: =F30*G30 -> 400
A31: 7 | B31: 1000 | C31: حسن الدرة | D31: 114 | E31: =VLOOKUP(D31, Home!$B$2:$C$100, 2, FALSE) -> سفره طاوله ١٥٢*١٣٧ - طرد ٣١١٢ | F31: 2 | G31: =VLOOKUP(D31, Home!$B$2:$G$1002, 6, FALSE) -> 400 | H31: =F31*G31 -> 800 | I31: =SUM(H23:H31) -> 6020
E493: =VLOOKUP(D493, Home!$B$2:$C$100, 2, FALSE) -> #N/A | G493: =VLOOKUP(D493, Home!$B$2:$G$1002, 6, FALSE) -> #N/A | H493: =F493*G493 -> #N/A
E494: =VLOOKUP(D494, Home!$B$2:$C$100, 2, FALSE) -> #N/A | G494: =VLOOKUP(D494, Home!$B$2:$G$1002, 6, FALSE) -> #N/A | H494: =F494*G494 -> #N/A
E495: =VLOOKUP(D495, Home!$B$2:$C$100, 2, FALSE) -> #N/A | G495: =VLOOKUP(D495, Home!$B$2:$G$1002, 6, FALSE) -> #N/A | H495: =F495*G495 -> #N/A
E496: =VLOOKUP(D496, Home!$B$2:$C$100, 2, FALSE) -> #N/A | G496: =VLOOKUP(D496, Home!$B$2:$G$1002, 6, FALSE) -> #N/A | H496: =F496*G496 -> #N/A
E497: =VLOOKUP(D497, Home!$B$2:$C$100, 2, FALSE) -> #N/A | G497: =VLOOKUP(D497, Home!$B$2:$G$1002, 6, FALSE) -> #N/A | H497: =F497*G497 -> #N/A
E498: =VLOOKUP(D498, Home!$B$2:$C$100, 2, FALSE) -> #N/A | G498: =VLOOKUP(D498, Home!$B$2:$G$1002, 6, FALSE) -> #N/A | H498: =F498*G498 -> #N/A
E499: =VLOOKUP(D499, Home!$B$2:$C$100, 2, FALSE) -> #N/A | G499: =VLOOKUP(D499, Home!$B$2:$G$1002, 6, FALSE) -> #N/A | H499: =F499*G499 -> #N/A
E500: =VLOOKUP(D500, Home!$B$2:$C$100, 2, FALSE) -> #N/A | G500: =VLOOKUP(D500, Home!$B$2:$G$1002, 6, FALSE) -> #N/A | H500: =F500*G500 -> #N/A
E501: =VLOOKUP(D501, Home!$B$2:$C$100, 2, FALSE) -> #N/A | G501: =VLOOKUP(D501, Home!$B$2:$G$1002, 6, FALSE) -> #N/A | H501: =F501*G501 -> #N/A
...

Sheet sales
A1: date | B1: invoice_id | C1: customer | D1: total | E1: pay | F1: on_account
A2: 45880 | B2: 1 | C2: مكتبة الصعيدي | D2: 30640 | E2: 25000 | F2: =SUM(Table1[[#This Row],[total]]-Table1[[#This Row],[pay]]) -> 5640
A3: 45728 | B3: 2 | C3: سوبر فتحة قبل الكريمي | D3: 2900 | E3: 2900 | F3: =SUM(Table1[[#This Row],[total]]-Table1[[#This Row],[pay]]) -> 0
A4: 45729 | B4: 3 | C4: عزام الشميري | D4: 3660 | E4: 2000 | F4: =SUM(Table1[[#This Row],[total]]-Table1[[#This Row],[pay]]) -> 1660
A5: 45730 | B5: 4 | C5: عزام الشميري | D5: 1000 | E5: 0 | F5: =SUM(Table1[[#This Row],[total]]-Table1[[#This Row],[pay]]) -> 1000
A6: 45761 | B6: 5 | C6: عزام الشميري | D6: 1000 | E6: 1000 | F6: =SUM(Table1[[#This Row],[total]]-Table1[[#This Row],[pay]]) -> 0
A7: 45762 | B7: 6 | C7: اكسسوارات الدايري | D7: 400 | E7: 400 | F7: =SUM(Table1[[#This Row],[total]]-Table1[[#This Row],[pay]]) -> 0
A8: 45763 | B8: 7 | C8: حسن الدرة | D8: 13240 | E8: 13240 | F8: =SUM(Table1[[#This Row],[total]]-Table1[[#This Row],[pay]]) -> 0
A9: 45794 | B9: 8 | C9: مكتبة يوسف العفيق | D9: 2400 | E9: 2000 | F9: =SUM(Table1[[#This Row],[total]]-Table1[[#This Row],[pay]]) -> 400
A10: 45795 | B10: 9 | C10: عمار جامعة تونتك | D10: 28450 | E10: 0 | F10: =SUM(Table1[[#This Row],[total]]-Table1[[#This Row],[pay]]) -> 28450
A11: 45827 | B11: 10 | C11: محمد فايز | D11: 3250 | E11: 3250 | F11: =SUM(Table1[[#This Row],[total]]-Table1[[#This Row],[pay]]) -> 0
A12: 45828 | B12: 11 | C12: بقالة تحت عمارة الروضة | D12: 4400 | E12: 0 | F12: =SUM(Table1[[#This Row],[total]]-Table1[[#This Row],[pay]]) -> 4400
A13: 45880 | B13: 12 | C13: تموينات الحبابي عطان | D13: 6425 | E13: 0 | F13: =SUM(Table1[[#This Row],[total]]-Table1[[#This Row],[pay]]) -> 6425
... A25: 46002 | B25: 24 | C25: حسان الاشول | D25: 8600 | E25: 0 | F25: =SUM(Table1[[#This Row],[total]]-Table1[[#This Row],[pay]]) -> 8600
E26: =SUM(Table1[pay]) -> 53340 | F26: =SUM(Table1[on_account]) -> 180245
F27: {=SUM(Table1[pay]+Table1[on_account])} -> 233585

Sheet accont_report
A1: Row Labels | B1: Sum of اجمالي السعر | C1: Sum of المدفوع | D1: Sum of المتبقي
A2: اكسسوارات الدايري | B2: 400 | C2: 400 | D2: 0
A3: بقالة تحت عمارة الروضة | B3: 4400 | C3: 0 | D3: 4400
A4: تموينات الحبابي عطان | B4: 6425 | C4: 0 | D4: 6425
A5: حسن الدرة | B5: 13240 | C5: 13240 | D5: 0
A6: سوبر جمب محمد فايز | B6: 62830 | C6: 0 | D6: 62830
A7: سوبر فتحة قبل الكريمي | B7: 2900 | C7: 2900 | D7: 0
A8: صيدلية الدكتور رؤف محمد فايز | B8: 10800 | C8: 0 | D8: 10800
A9: عادل الدبعي | B9: 5270 | C9: 0 | D9: 5270
A10: عبدالسلام الاشول | B10: 4750 | C10: 0 | D10: 4750
A11: عزام الشميري | B11: 7660 | C11: 3000 | D11: 4660
A12: عمار جامعة تونتك | B12: 28450 | C12: 0 | D12: 28450
A13: محمد فايز | B13: 8350 | C13: 6800 | D13: 1550
... A17: Grand Total | B17: 232695 | C17: 53340 | D17: 179355

Sheet cach_resive
A1: date | B1: customer | C1: amount
A2: 45727 | B2: مكتبة الصعيدي | C2: 14000
A3: 45728 | B3: سوبر فتحة قبل الكريمي | C3: 2900
A4: 45729 | B4: عزام الشميري | C4: 2000
A5: 45761 | B5: عزام الشميري | C5: 1000
A6: 45762 | B6: اكسسوارات الدايري | C6: 400
A7: 45763 | B7: حسن الدرة | C7: 13240
A8: 45794 | B8: مكتبة يوسف العفيق | C8: 2000
A9: 45795 | B9: مكتبة الصعيدي | C9: 3000
A10: 45880 | B10: مكتبة الصعيدي | C10: 8000
A11: 45911 | B11: محمد فايز | C11: 6800
C12: =SUM(Table2[amount]) -> 53340
